Workbook

Sheet Keyword Map
A1: Website Keyword Map – one primary keyword per page
A2: Source: Semrush Keyword Magic (India database) exports + agency-side bulk run, shared by the user 13 Oct 2026. Cluster volume = SUMIFS over 'All Keywords' by assigned page.
A3: Phase 1 = build first (months 0–2) · Phase 2 = months 2–5 · Phase 3 = later / early bets
A5: Phase | B5: Section | C5: URL | D5: Page | E5: Primary keyword | F5: Primary volume | G5: Primary KD % | H5: Secondary keywords | I5: # keywords | J5: Cluster volume | K5: Cluster value (USD/mo)
A6: 1 | B6: Ads | C6: /amazon-marketing-agency/ | D6: Amazon Advertising Agency | E6: amazon advertising agency | F6: =SUMIFS('All Keywords'!$B$2:$B$1170,'All Keywords'!$A$2:$A$1170,E6) -> 390 | G6: =SUMIFS('All Keywords'!$C$2:$C$1170,'All Keywords'!$A$2:$A$1170,E6) -> 17 | H6: ad agency for amazon, amazon ad agency, amazon marketing agency india, amazon marketing agency, amazon ppc agency, amazon advertising agency india | I6: =COUNTIFS('All Keywords'!$H$2:$H$1170,C6) -> 7 | J6: =SUMIFS('All Keywords'!$B$2:$B$1170,'All Keywords'!$H$2:$H$1170,C6) -> 1940 | K6: =SUMIFS('All Keywords'!$I$2:$I$1170,'All Keywords'!$H$2:$H$1170,C6) -> 2036.5
A7: 1 | B7: Ads | C7: /amazon-account-management/ | D7: Amazon Account Management | E7: amazon account management services | F7: =SUMIFS('All Keywords'!$B$2:$B$1170,'All Keywords'!$A$2:$A$1170,E7) -> 720 | G7: =SUMIFS('All Keywords'!$C$2:$C$1170,'All Keywords'!$A$2:$A$1170,E7) -> 23 | I7: =COUNTIFS('All Keywords'!$H$2:$H$1170,C7) -> 1 | J7: =SUMIFS('All Keywords'!$B$2:$B$1170,'All Keywords'!$H$2:$H$1170,C7) -> 720 | K7: =SUMIFS('All Keywords'!$I$2:$I$1170,'All Keywords'!$H$2:$H$1170,C7) -> 439.2
A8: 1 | B8: Ads | C8: /flipkart-account-management/ | D8: Flipkart Account & Ads Management | E8: flipkart account management services | F8: =SUMIFS('All Keywords'!$B$2:$B$1170,'All Keywords'!$A$2:$A$1170,E8) -> 320 | G8: =SUMIFS('All Keywords'!$C$2:$C$1170,'All Keywords'!$A$2:$A$1170,E8) -> 12 | H8: flipkart ads management | I8: =COUNTIFS('All Keywords'!$H$2:$H$1170,C8) -> 2 | J8: =SUMIFS('All Keywords'!$B$2:$B$1170,'All Keywords'!$H$2:$H$1170,C8) -> 320 | K8: =SUMIFS('All Keywords'!$I$2:$I$1170,'All Keywords'!$H$2:$H$1170,C8) -> 192
A9: 1 | B9: Chennai | C9: /chennai/digital-marketing-agency/ | D9: Digital Marketing Agency in Chennai | E9: digital marketing agency chennai | F9: =SUMIFS('All Keywords'!$B$2:$B$1170,'All Keywords'!$A$2:$A$1170,E9) -> 5400 | G9: =SUMIFS('All Keywords'!$C$2:$C$1170,'All Keywords'!$A$2:$A$1170,E9) -> 17 | I9: =COUNTIFS('All Keywords'!$H$2:$H$1170,C9) -> 1 | J9: =SUMIFS('All Keywords'!$B$2:$B$1170,'All Keywords'!$H$2:$H$1170,C9) -> 5400 | K9: =SUMIFS('All Keywords'!$I$2:$I$1170,'All Keywords'!$H$2:$H$1170,C9) -> 2322
A10: 1 | B10: Chennai | C10: /chennai/seo-company/ | D10: SEO Company in Chennai | E10: seo company in chennai | F10: =SUMIFS('All Keywords'!$B$2:$B$1170,'All Keywords'!$A$2:$A$1170,E10) -> 2900 | G10: =SUMIFS('All Keywords'!$C$2:$C$1170,'All Keywords'!$A$2:$A$1170,E10) -> 29 | H10: seo agency in chennai, seo expert in chennai, seo in chennai, best seo agency in chennai, best seo services in chennai, seo agency chennai, seo services company in chennai | I10: =COUNTIFS('All Keywords'!$H$2:$H$1170,C10) -> 8 | J10: =SUMIFS('All Keywords'!$B$2:$B$1170,'All Keywords'!$H$2:$H$1170,C10) -> 4600 | K10: =SUMIFS('All Keywords'!$I$2:$I$1170,'All Keywords'!$H$2:$H$1170,C10) -> 2582
A11: 1 | B11: Chennai | C11: /chennai/ecommerce-website-development/ | D11: E-commerce Website Development in Chennai | E11: ecommerce website development company in chennai | F11: =SUMIFS('All Keywords'!$B$2:$B$1170,'All Keywords'!$A$2:$A$1170,E11) -> 320 | G11: =SUMIFS('All Keywords'!$C$2:$C$1170,'All Keywords'!$A$2:$A$1170,E11) -> 28 | H11: ecommerce website development in chennai, ecommerce web development chennai, ecommerce development company in chennai, ecommerce website development chennai, shopify experts in chennai, shopify experts chennai | I11: =COUNTIFS('All Keywords'!$H$2:$H$1170,C11) -> 7 | J11: =SUMIFS('All Keywords'!$B$2:$B$1170,'All Keywords'!$H$2:$H$1170,C11) -> 980 | K11: =SUMIFS('All Keywords'!$I$2:$I$1170,'All Keywords'!$H$2:$H$1170,C11) -> 160
A12: 1 | B12: Content | C12: /blog/ecommerce-website-cost-in-india/ | D12: Guide: E-commerce Website Cost in India | E12: ecommerce website cost in india | F12: =SUMIFS('All Keywords'!$B$2:$B$1170,'All Keywords'!$A$2:$A$1170,E12) -> 170 | G12: =SUMIFS('All Keywords'!$C$2:$C$1170,'All Keywords'!$A$2:$A$1170,E12) -> 6 | H12: best ecommerce platform in india | I12: =COUNTIFS('All Keywords'!$H$2:$H$1170,C12) -> 2 | J12: =SUMIFS('All Keywords'!$B$2:$B$1170,'All Keywords'!$H$2:$H$1170,C12) -> 430 | K12: =SUMIFS('All Keywords'!$I$2:$I$1170,'All Keywords'!$H$2:$H$1170,C12) -> 125.6
A13: 1 | B13: Core | C13: / | D13: Home – E-commerce Growth Agency | E13: ecommerce marketing agency | F13: =SUMIFS('All Keywords'!$B$2:$B$1170,'All Keywords'!$A$2:$A$1170,E13) -> 480 | G13: =SUMIFS('All Keywords'!$C$2:$C$1170,'All Keywords'!$A$2:$A$1170,E13) -> 11 | H13: ecommerce agency near me, ecommerce marketing agency india | I13: =COUNTIFS('All Keywords'!$H$2:$H$1170,C13) -> 3 | J13: =SUMIFS('All Keywords'!$B$2:$B$1170,'All Keywords'!$H$2:$H$1170,C13) -> 970 | K13: =SUMIFS('All Keywords'!$I$2:$I$1170,'All Keywords'!$H$2:$H$1170,C13) -> 595.9
A14: 1 | B14: SEO | C14: /ecommerce-seo/ | D14: E-commerce SEO Services | E14: ecommerce seo services | F14: =SUMIFS('All Keywords'!$B$2:$B$1170,'All Keywords'!$A$2:$A$1170,E14) -> 1000 | G14: =SUMIFS('All Keywords'!$C$2:$C$1170,'All Keywords'!$A$2:$A$1170,E14) -> 11 | H14: ecommerce search engine optimization services, best ecommerce seo services in india, affordable ecommerce seo services, ecommerce seo services india, ecommerce seo consultant, ecommerce seo agency | I14: =COUNTIFS('All Keywords'!$H$2:$H$1170,C14) -> 7 | J14: =SUMIFS('All Keywords'!$B$2:$B$1170,'All Keywords'!$H$2:$H$1170,C14) -> 3350 | K14: =SUMIFS('All Keywords'!$I$2:$I$1170,'All Keywords'!$H$2:$H$1170,C14) -> 2166.4
A15: 1 | B15: SEO | C15: /ecommerce-seo-packages/ | D15: E-commerce SEO Packages & Pricing | E15: ecommerce website seo packages | F15: =SUMIFS('All Keywords'!$B$2:$B$1170,'All Keywords'!$A$2:$A$1170,E15) -> 390 | G15: =SUMIFS('All Keywords'!$C$2:$C$1170,'All Keywords'!$A$2:$A$1170,E15) -> 17 | H15: ecommerce seo packages | I15: =COUNTIFS('All Keywords'!$H$2:$H$1170,C15) -> 2 | J15: =SUMIFS('All Keywords'!$B$2:$B$1170,'All Keywords'!$H$2:$H$1170,C15) -> 530 | K15: =SUMIFS('All Keywords'!$I$2:$I$1170,'All Keywords'!$H$2:$H$1170,C15) -> 140.4
A16: 1 | B16: Website | C16: /shopify-development/ | D16: Shopify Development Company | E16: shopify website development company | F16: =SUMIFS('All Keywords'!$B$2:$B$1170,'All Keywords'!$A$2:$A$1170,E16) -> 1300 | G16: =SUMIFS('All Keywords'!$C$2:$C$1170,'All Keywords'!$A$2:$A$1170,E16) -> 24 | H16: best shopify development company, shopify development agency, shopify agency, shopify development company in india, top shopify development companies, shopify website development agency, shopify experts india, shopify development company india, shopify developer india, shopify developer near me | I16: =COUNTIFS('All Keywords'!$H$2:$H$1170,C16) -> 11 | J16: =SUMIFS('All Keywords'!$B$2:$B$1170,'All Keywords'!$H$2:$H$1170,C16) -> 5490 | K16: =SUMIFS('All Keywords'!$I$2:$I$1170,'All Keywords'!$H$2:$H$1170,C16) -> 2714.1
A17: 1 | B17: Website | C17: /ecommerce-website-development/ | D17: E-commerce Website Development | E17: ecommerce website development company | F17: =SUMIFS('All Keywords'!$B$2:$B$1170,'All Keywords'!$A$2:$A$1170,E17) -> 1000 | G17: =SUMIFS('All Keywords'!$C$2:$C$1170,'All Keywords'!$A$2:$A$1170,E17) -> 27 | H17: ecommerce development company india, ecommerce solution company, wordpress ecommerce development company, hire ecommerce developer | I17: =COUNTIFS('All Keywords'!$H$2:$H$1170,C17) -> 5 | J17: =SUMIFS('All Keywords'!$B$2:$B$1170,'All Keywords'!$H$2:$H$1170,C17) -> 1880 | K17: =SUMIFS('All Keywords'!$I$2:$I$1170,'All Keywords'!$H$2:$H$1170,C17) -> 1366.2
A18: 2 | B18: Ads | C18: /shopify-marketing/ | D18: Shopify Marketing Agency | E18: shopify digital marketing agency | F18: =SUMIFS('All Keywords'!$B$2:$B$1170,'All Keywords'!$A$2:$A$1170,E18) -> 260 | G18: =SUMIFS('All Keywords'!$C$2:$C$1170,'All Keywords'!$A$2:$A$1170,E18) -> 11 | H18: shopify marketing agency | I18: =COUNTIFS('All Keywords'!$H$2:$H$1170,C18) -> 2 | J18: =SUMIFS('All Keywords'!$B$2:$B$1170,'All Keywords'!$H$2:$H$1170,C18) -> 470 | K18: =SUMIFS('All Keywords'!$I$2:$I$1170,'All Keywords'!$H$2:$H$1170,C18) -> 479.8
A19: 2 | B19: Ads | C19: /ecommerce-social-media-marketing/ | D19: E-commerce Social Media Marketing | E19: ecommerce social media marketing agency | F19: =SUMIFS('All Keywords'!$B$2:$B$1170,'All Keywords'!$A$2:$A$1170,E19) -> 390 | G19: =SUMIFS('All Keywords'!$C$2:$C$1170,'All Keywords'!$A$2:$A$1170,E19) -> 29 | H19: social media marketing agency for ecommerce | I19: =COUNTIFS('All Keywords'!$H$2:$H$1170,C19) -> 2 | J19: =SUMIFS('All Keywords'!$B$2:$B$1170,'All Keywords'!$H$2:$H$1170,C19) -> 600 | K19: =SUMIFS('All Keywords'!$I$2:$I$1170,'All Keywords'!$H$2:$H$1170,C19) -> 479.7
A20: 2 | B20: Ads | C20: /performance-marketing/ | D20: Performance Marketing Agency | E20: performance marketing agency india | F20: =SUMIFS('All Keywords'!$B$2:$B$1170,'All Keywords'!$A$2:$A$1170,E20) -> 320 | G20: =SUMIFS('All Keywords'!$C$2:$C$1170,'All Keywords'!$A$2:$A$1170,E20) -> 19 | I20: =COUNTIFS('All Keywords'!$H$2:$H$1170,C20) -> 1 | J20: =SUMIFS('All Keywords'!$B$2:$B$1170,'All Keywords'!$H$2:$H$1170,C20) -> 320 | K20: =SUMIFS('All Keywords'!$I$2:$I$1170,'All Keywords'!$H$2:$H$1170,C20) -> 262.4
A21: 2 | B21: B2B/Export | C21: /b2b-digital-marketing/ | D21: B2B Digital Marketing for Manufacturers & Exporters | E21: b2b digital marketing services | F21: =SUMIFS('All Keywords'!$B$2:$B$1170,'All Keywords'!$A$2:$A$1170,E21) -> 1900 | G21: =SUMIFS('All Keywords'!$C$2:$C$1170,'All Keywords'!$A$2:$A$1170,E21) -> 15 | H21: b2b marketing agency, b2b advertising agency, b2b seo agency, digital marketing agency for b2b, b2b lead generation company india, seo for manufacturers, digital marketing for manufacturers, digital marketing for manufacturing industry | I21: =COUNTIFS('All Keywords'!$H$2:$H$1170,C21) -> 9 | J21: =SUMIFS('All Keywords'!$B$2:$B$1170,'All Keywords'!$H$2:$H$1170,C21) -> 4410 | K21: =SUMIFS('All Keywords'!$I$2:$I$1170,'All Keywords'!$H$2:$H$1170,C21) -> 6014.1
A22: 2 | B22: Content | C22: /blog/how-to-find-buyers-for-export/ | D22: Guide: How to Find Export Buyers | E22: how to find buyers for export | F22: =SUMIFS('All Keywords'!$B$2:$B$1170,'All Keywords'!$A$2:$A$1170,E22) -> 390 | G22: =SUMIFS('All Keywords'!$C$2:$C$1170,'All Keywords'!$A$2:$A$1170,E22) -> 15 | H22: how to get export orders, how to get international buyers | I22: =COUNTIFS('All Keywords'!$H$2:$H$1170,C22) -> 3 | J22: =SUMIFS('All Keywords'!$B$2:$B$1170,'All Keywords'!$H$2:$H$1170,C22) -> 440 | K22: =SUMIFS('All Keywords'!$I$2:$I$1170,'All Keywords'!$H$2:$H$1170,C22) -> 96
A23: 2 | B23: Global | C23: /white-label-seo/ | D23: White-label SEO for Agencies | E23: white label seo services | F23: =SUMIFS('All Keywords'!$B$2:$B$1170,'All Keywords'!$A$2:$A$1170,E23) -> 590 | G23: =SUMIFS('All Keywords'!$C$2:$C$1170,'All Keywords'!$A$2:$A$1170,E23) -> 27 | H23: white label seo agency, white label seo services for agencies, white label local seo services | I23: =COUNTIFS('All Keywords'!$H$2:$H$1170,C23) -> 4 | J23: =SUMIFS('All Keywords'!$B$2:$B$1170,'All Keywords'!$H$2:$H$1170,C23) -> 1410 | K23: =SUMIFS('All Keywords'!$I$2:$I$1170,'All Keywords'!$H$2:$H$1170,C23) -> 1243.4
A24: 2 | B24: Global | C24: /seo-outsourcing-india/ | D24: Outsource SEO to India | E24: seo outsourcing india | F24: =SUMIFS('All Keywords'!$B$2:$B$1170,'All Keywords'!$A$2:$A$1170,E24) -> 880 | G24: =SUMIFS('All Keywords'!$C$2:$C$1170,'All Keywords'!$A$2:$A$1170,E24) -> 17 | H24: outsource seo company india, seo outsourcing company india, seo outsourcing company in india, outsource seo services, outsource seo services to india, seo outsourcing company | I24: =COUNTIFS('All Keywords'!$H$2:$H$1170,C24) -> 7 | J24: =SUMIFS('All Keywords'!$B$2:$B$1170,'All Keywords'!$H$2:$H$1170,C24) -> 2890 | K24: =SUMIFS('All Keywords'!$I$2:$I$1170,'All Keywords'!$H$2:$H$1170,C24) -> 2818.9
A25: 2 | B25: SEO | C25: /shopify-seo/ | D25: Shopify SEO Services | E25: shopify seo services | F25: =SUMIFS('All Keywords'!$B$2:$B$1170,'All Keywords'!$A$2:$A$1170,E25) -> 720 | G25: =SUMIFS('All Keywords'!$C$2:$C$1170,'All Keywords'!$A$2:$A$1170,E25) -> 26 | I25: =COUNTIFS('All Keywords'!$H$2:$H$1170,C25) -> 1 | J25: =SUMIFS('All Keywords'!$B$2:$B$1170,'All Keywords'!$H$2:$H$1170,C25) -> 720 | K25: =SUMIFS('All Keywords'!$I$2:$I$1170,'All Keywords'!$H$2:$H$1170,C25) -> 540
A26: 2 | B26: SEO | C26: /amazon-seo/ | D26: Amazon SEO & Listing Optimisation | E26: amazon seo services | F26: =SUMIFS('All Keywords'!$B$2:$B$1170,'All Keywords'!$A$2:$A$1170,E26) -> 260 | G26: =SUMIFS('All Keywords'!$C$2:$C$1170,'All Keywords'!$A$2:$A$1170,E26) -> 10 | H26: seo services amazon, amazon listing optimization service | I26: =COUNTIFS('All Keywords'!$H$2:$H$1170,C26) -> 3 | J26: =SUMIFS('All Keywords'!$B$2:$B$1170,'All Keywords'!$H$2:$H$1170,C26) -> 540 | K26: =SUMIFS('All Keywords'!$I$2:$I$1170,'All Keywords'!$H$2:$H$1170,C26) -> 336.2
A27: 2 | B27: SEO | C27: /seo-services/ | D27: SEO Services (all businesses) | E27: seo agency india | F27: =SUMIFS('All Keywords'!$B$2:$B$1170,'All Keywords'!$A$2:$A$1170,E27) -> 9900 | G27: =SUMIFS('All Keywords'!$C$2:$C$1170,'All Keywords'!$A$2:$A$1170,E27) -> 28 | H27: local seo services, affordable local seo services, small business seo services, seo consultant, seo expert from india | I27: =COUNTIFS('All Keywords'!$H$2:$H$1170,C27) -> 6 | J27: =SUMIFS('All Keywords'!$B$2:$B$1170,'All Keywords'!$H$2:$H$1170,C27) -> 18700 | K27: =SUMIFS('All Keywords'!$I$2:$I$1170,'All Keywords'!$H$2:$H$1170,C27) -> 9465
A28: 2 | B28: SEO | C28: /seo-packages/ | D28: SEO Packages & Pricing India | E28: seo packages | F28: =SUMIFS('All Keywords'!$B$2:$B$1170,'All Keywords'!$A$2:$A$1170,E28) -> 1000 | G28: =SUMIFS('All Keywords'!$C$2:$C$1170,'All Keywords'!$A$2:$A$1170,E28) -> 14 | H28: seo packages india, seo cost in india, seo charges in india, seo price in india | I28: =COUNTIFS('All Keywords'!$H$2:$H$1170,C28) -> 5 | J28: =SUMIFS('All Keywords'!$B$2:$B$1170,'All Keywords'!$H$2:$H$1170,C28) -> 4880 | K28: =SUMIFS('All Keywords'!$I$2:$I$1170,'All Keywords'!$H$2:$H$1170,C28) -> 2511.6
A29: 2 | B29: Website | C29: /woocommerce-development/ | D29: WooCommerce Development | E29: woocommerce development company | F29: =SUMIFS('All Keywords'!$B$2:$B$1170,'All Keywords'!$A$2:$A$1170,E29) -> 720 | G29: =SUMIFS('All Keywords'!$C$2:$C$1170,'All Keywords'!$A$2:$A$1170,E29) -> 22 | H29: hire woocommerce developer | I29: =COUNTIFS('All Keywords'!$H$2:$H$1170,C29) -> 2 | J29: =SUMIFS('All Keywords'!$B$2:$B$1170,'All Keywords'!$H$2:$H$1170,C29) -> 830 | K29: =SUMIFS('All Keywords'!$I$2:$I$1170,'All Keywords'!$H$2:$H$1170,C29) -> 0
A30: 3 | B30: Ads | C30: /quick-commerce-marketing/ | D30: Blinkit / Zepto / Instamart Ads (early bet) | E30: quick commerce marketing agency | F30: =SUMIFS('All Keywords'!$B$2:$B$1170,'All Keywords'!$A$2:$A$1170,E30) -> 0 | G30: =SUMIFS('All Keywords'!$C$2:$C$1170,'All Keywords'!$A$2:$A$1170,E30) -> 7 | H30: blinkit ads | I30: =COUNTIFS('All Keywords'!$H$2:$H$1170,C30) -> 2 | J30: =SUMIFS('All Keywords'!$B$2:$B$1170,'All Keywords'!$H$2:$H$1170,C30) -> 0 | K30: =SUMIFS('All Keywords'!$I$2:$I$1170,'All Keywords'!$H$2:$H$1170,C30) -> 0
A31: 3 | B31: Chennai | C31: /coimbatore/seo-services/ | D31: SEO Services in Coimbatore | E31: seo services in coimbatore | F31: =SUMIFS('All Keywords'!$B$2:$B$1170,'All Keywords'!$A$2:$A$1170,E31) -> 590 | G31: =SUMIFS('All Keywords'!$C$2:$C$1170,'All Keywords'!$A$2:$A$1170,E31) -> 28 | H31: seo agency in coimbatore | I31: =COUNTIFS('All Keywords'!$H$2:$H$1170,C31) -> 2 | J31: =SUMIFS('All Keywords'!$B$2:$B$1170,'All Keywords'!$H$2:$H$1170,C31) -> 850 | K31: =SUMIFS('All Keywords'!$I$2:$I$1170,'All Keywords'!$H$2:$H$1170,C31) -> 314
D32: TOTAL | I32: =SUM(I6:I31) -> 105 | J32: =SUM(J6:J31) -> 63670 | K32: =SUM(K6:K31) -> 39401.4
D33: Phase 1 volume | J33: =SUMIFS(J6:J31,A6:A31,1) -> 26610
D34: Phase 2 volume | J34: =SUMIFS(J6:J31,A6:A31,2) -> 36210
D35: Phase 3 volume | J35: =SUMIFS(J6:J31,A6:A31,3) -> 850

Sheet All Keywords
A1: Keyword | B1: Volume | C1: KD % | D1: CPC (USD) | E1: Intent | F1: Semrush seed | G1: Category | H1: Assigned page | I1: Value (Vol×CPC)
A2: seo company in chennai | B2: 2900 | C2: 29 | D2: 0.55 | E2: Commercial | F2: seo_services | G2: Tamil Nadu local | H2: /chennai/seo-company/ | I2: =IF(AND(ISNUMBER(B2),ISNUMBER(D2)),B2*D2,0) -> 1595
A3: seo services in coimbatore | B3: 590 | C3: 28 | D3: 0.4 | E3: Commercial | F3: seo_services | G3: Tamil Nadu local | H3: /coimbatore/seo-services/ | I3: =IF(AND(ISNUMBER(B3),ISNUMBER(D3)),B3*D3,0) -> 236
A4: seo agency in chennai | B4: 480 | C4: 27 | D4: 0.55 | E4: Commercial | F4: seo_services | G4: Tamil Nadu local | H4: /chennai/seo-company/ | I4: =IF(AND(ISNUMBER(B4),ISNUMBER(D4)),B4*D4,0) -> 264
A5: seo expert in chennai | B5: 390 | C5: 26 | D5: 0.73 | E5: Commercial | F5: seo_services | G5: Tamil Nadu local | H5: /chennai/seo-company/ | I5: =IF(AND(ISNUMBER(B5),ISNUMBER(D5)),B5*D5,0) -> 284.7
A6: ecommerce website development company in chennai | B6: 320 | C6: 28 | D6: 0.5 | E6: Commercial | F6: website_development_company | G6: Tamil Nadu local | H6: /chennai/ecommerce-website-development/ | I6: =IF(AND(ISNUMBER(B6),ISNUMBER(D6)),B6*D6,0) -> 160
A7: seo in chennai | B7: 260 | C7: 26 | D7: 0.68 | E7: Commercial | F7: seo_services | G7: Tamil Nadu local | H7: /chennai/seo-company/ | I7: =IF(AND(ISNUMBER(B7),ISNUMBER(D7)),B7*D7,0) -> 176.8
A8: seo agency in coimbatore | B8: 260 | C8: 29 | D8: 0.3 | E8: Commercial | F8: seo_services | G8: Tamil Nadu local | H8: /coimbatore/seo-services/ | I8: =IF(AND(ISNUMBER(B8),ISNUMBER(D8)),B8*D8,0) -> 78
A9: best seo agency in chennai | B9: 210 | C9: 26 | D9: 0.61 | E9: Commercial | F9: seo_services | G9: Tamil Nadu local | H9: /chennai/seo-company/ | I9: =IF(AND(ISNUMBER(B9),ISNUMBER(D9)),B9*D9,0) -> 128.1
A10: ecommerce web development chennai | B10: 170 | C10: 15 | D10: 0 | E10: Commercial | F10: website_development_company | G10: Tamil Nadu local | H10: /chennai/ecommerce-website-development/ | I10: =IF(AND(ISNUMBER(B10),ISNUMBER(D10)),B10*D10,0) -> 0
A11: ecommerce website development in chennai | B11: 170 | C11: 25 | D11: 0 | E11: Informational | F11: website_development_company | G11: Tamil Nadu local | H11: /chennai/ecommerce-website-development/ | I11: =IF(AND(ISNUMBER(B11),ISNUMBER(D11)),B11*D11,0) -> 0
A12: best seo services in chennai | B12: 140 | C12: 28 | D12: 0.45 | E12: Commercial | F12: seo_services | G12: Tamil Nadu local | H12: /chennai/seo-company/ | I12: =IF(AND(ISNUMBER(B12),ISNUMBER(D12)),B12*D12,0) -> 63
A13: ecommerce development company in chennai | B13: 110 | C13: 24 | D13: 0 | E13: Commercial | F13: website_development_company | G13: Tamil Nadu local | H13: /chennai/ecommerce-website-development/ | I13: =IF(AND(ISNUMBER(B13),ISNUMBER(D13)),B13*D13,0) -> 0
... A19: best shopify development company | B19: 1300 | C19: 21 | D19: 0 | E19: Commercial | F19: shopify_agency | G19: E-commerce / Shopify / Amazon | H19: /shopify-development/ | I19: =IF(AND(ISNUMBER(B19),ISNUMBER(D19)),B19*D19,0) -> 0
A20: shopify website development company | B20: 1300 | C20: 24 | D20: 0.57 | F20: shopify_agency | G20: E-commerce / Shopify / Amazon | H20: /shopify-development/ | I20: =IF(AND(ISNUMBER(B20),ISNUMBER(D20)),B20*D20,0) -> 741
A21: ecommerce search engine optimization services | B21: 1000 | C21: 21 | D21: 0.98 | E21: Informational | F21: seo_services | G21: E-commerce / Shopify / Amazon | H21: /ecommerce-seo/ | I21: =IF(AND(ISNUMBER(B21),ISNUMBER(D21)),B21*D21,0) -> 980
A22: ecommerce seo services | B22: 1000 | C22: 11 | D22: 1.15 | E22: Informational | F22: seo_services | G22: E-commerce / Shopify / Amazon | H22: /ecommerce-seo/ | I22: =IF(AND(ISNUMBER(B22),ISNUMBER(D22)),B22*D22,0) -> 1150
A23: ecommerce website development company | B23: 1000 | C23: 27 | D23: 0.87 | E23: Commercial | F23: agency-side bulk run | G23: E-commerce / Shopify / Amazon | H23: /ecommerce-website-development/ | I23: =IF(AND(ISNUMBER(B23),ISNUMBER(D23)),B23*D23,0) -> 870
A24: shopify seo services | B24: 720 | C24: 26 | D24: 0.75 | E24: Informational, Commercial | F24: shopify_agency | G24: E-commerce / Shopify / Amazon | H24: /shopify-seo/ | I24: =IF(AND(ISNUMBER(B24),ISNUMBER(D24)),B24*D24,0) -> 540
A25: woocommerce development company | B25: 720 | C25: 22 | D25: 0 | E25: Informational | F25: agency-side bulk run | G25: E-commerce / Shopify / Amazon | H25: /woocommerce-development/ | I25: =IF(AND(ISNUMBER(B25),ISNUMBER(D25)),B25*D25,0) -> 0
A26: amazon account management services | B26: 720 | C26: 23 | D26: 0.61 | E26: Informational | F26: agency-side bulk run | G26: E-commerce / Shopify / Amazon | H26: /amazon-account-management/ | I26: =IF(AND(ISNUMBER(B26),ISNUMBER(D26)),B26*D26,0) -> 439.2
A27: shopify development agency | B27: 590 | C27: 26 | D27: 0.75 | F27: shopify_agency | G27: E-commerce / Shopify / Amazon | H27: /shopify-development/ | I27: =IF(AND(ISNUMBER(B27),ISNUMBER(D27)),B27*D27,0) -> 442.5
A28: currency formatting shopify | B28: 590 | C28: 22 | D28: 0 | E28: Informational | F28: shopify_agency | G28: E-commerce / Shopify / Amazon | I28: =IF(AND(ISNUMBER(B28),ISNUMBER(D28)),B28*D28,0) -> 0
A29: best ecommerce seo services in india | B29: 590 | C29: 9 | D29: 0 | E29: Commercial | F29: digital_marketing_company | G29: E-commerce / Shopify / Amazon | H29: /ecommerce-seo/ | I29: =IF(AND(ISNUMBER(B29),ISNUMBER(D29)),B29*D29,0) -> 0
A30: shopify agency | B30: 480 | C30: 27 | D30: 0.7 | E30: Informational | F30: shopify_agency | G30: E-commerce / Shopify / Amazon | H30: /shopify-development/ | I30: =IF(AND(ISNUMBER(B30),ISNUMBER(D30)),B30*D30,0) -> 336
A31: shopify development company in india | B31: 480 | C31: 29 | D31: 0.51 | E31: Informational, Commercial | F31: shopify_agency | G31: E-commerce / Shopify / Amazon | H31: /shopify-development/ | I31: =IF(AND(ISNUMBER(B31),ISNUMBER(D31)),B31*D31,0) -> 244.8
A32: ecommerce marketing agency | B32: 480 | C32: 11 | D32: 0.74 | E32: Commercial | F32: agency-side bulk run | G32: E-commerce / Shopify / Amazon | H32: / | I32: =IF(AND(ISNUMBER(B32),ISNUMBER(D32)),B32*D32,0) -> 355.2
A33: top shopify development companies | B33: 390 | C33: 19 | D33: 0 | E33: Commercial | F33: shopify_agency | G33: E-commerce / Shopify / Amazon | H33: /shopify-development/ | I33: =IF(AND(ISNUMBER(B33),ISNUMBER(D33)),B33*D33,0) -> 0
A34: shopifypartner | B34: 390 | C34: 29 | D34: 0 | E34: Navigational | F34: shopify_agency | G34: E-commerce / Shopify / Amazon | I34: =IF(AND(ISNUMBER(B34),ISNUMBER(D34)),B34*D34,0) -> 0
A35: ecommerce development company india | B35: 390 | C35: 26 | D35: 0.68 | E35: C | F35: website_development_company | G35: E-commerce / Shopify / Amazon | H35: /ecommerce-website-development/ | I35: =IF(AND(ISNUMBER(B35),ISNUMBER(D35)),B35*D35,0) -> 265.2
A36: ecommerce social media marketing agency | B36: 390 | C36: 29 | D36: 1.23 | E36: C | F36: digital_marketing_company | G36: E-commerce / Shopify / Amazon | H36: /ecommerce-social-media-marketing/ | I36: =IF(AND(ISNUMBER(B36),ISNUMBER(D36)),B36*D36,0) -> 479.7
A37: ad agency for amazon | B37: 390 | C37: 10 | D37: 1.06 | E37: Informational, Commercial | F37: digital_marketing_company | G37: E-commerce / Shopify / Amazon | H37: /amazon-marketing-agency/ | I37: =IF(AND(ISNUMBER(B37),ISNUMBER(D37)),B37*D37,0) -> 413.4
A38: amazon ad agency | B38: 390 | C38: 24 | D38: 1.06 | E38: Informational | F38: digital_marketing_company | G38: E-commerce / Shopify / Amazon | H38: /amazon-marketing-agency/ | I38: =IF(AND(ISNUMBER(B38),ISNUMBER(D38)),B38*D38,0) -> 413.4
A39: amazon advertising agency | B39: 390 | C39: 17 | D39: 1.06 | E39: Informational | F39: digital_marketing_company | G39: E-commerce / Shopify / Amazon | H39: /amazon-marketing-agency/ | I39: =IF(AND(ISNUMBER(B39),ISNUMBER(D39)),B39*D39,0) -> 413.4
A40: ecommerce website seo packages | B40: 390 | C40: 17 | D40: 0.36 | E40: Informational | F40: seo_services | G40: E-commerce / Shopify / Amazon | H40: /ecommerce-seo-packages/ | I40: =IF(AND(ISNUMBER(B40),ISNUMBER(D40)),B40*D40,0) -> 140.4
A41: how to find buyers for export | B41: 390 | C41: 15 | D41: 0.22 | E41: Informational | F41: agency-side bulk run | G41: E-commerce / Shopify / Amazon | H41: /blog/how-to-find-buyers-for-export/ | I41: =IF(AND(ISNUMBER(B41),ISNUMBER(D41)),B41*D41,0) -> 85.8
A42: shopify plus agency | B42: 320 | C42: 27 | D42: 0.36 | E42: Informational | F42: shopify_agency | G42: E-commerce / Shopify / Amazon | I42: =IF(AND(ISNUMBER(B42),ISNUMBER(D42)),B42*D42,0) -> 115.2
A43: shopify app development company | B43: 320 | C43: 28 | D43: 1.9 | E43: Commercial | F43: shopify_agency | G43: E-commerce / Shopify / Amazon | I43: =IF(AND(ISNUMBER(B43),ISNUMBER(D43)),B43*D43,0) -> 608
A44: amazon marketing agency india | B44: 320 | C44: 10 | D44: 0.79 | E44: Commercial | F44: digital_marketing_company | G44: E-commerce / Shopify / Amazon | H44: /amazon-marketing-agency/ | I44: =IF(AND(ISNUMBER(B44),ISNUMBER(D44)),B44*D44,0) -> 252.8
A45: ecommerce agency near me | B45: 320 | C45: 13 | D45: 0.46 | E45: Transactional | F45: digital_marketing_company | G45: E-commerce / Shopify / Amazon | H45: / | I45: =IF(AND(ISNUMBER(B45),ISNUMBER(D45)),B45*D45,0) -> 147.2
...

Sheet Category Summary
A1: Where the 1,147 keywords fall
A3: Category | B3: Keywords | C3: Total volume | D3: Avg KD %
A4: Tamil Nadu local | B4: =COUNTIFS('All Keywords'!$G$2:$G$1170,A4) -> 16 | C4: =SUMIFS('All Keywords'!$B$2:$B$1170,'All Keywords'!$G$2:$G$1170,A4) -> 6260 | D4: =IFERROR(AVERAGEIFS('All Keywords'!$C$2:$C$1170,'All Keywords'!$G$2:$G$1170,A4),"") -> 23.9375
A5: E-commerce / Shopify / Amazon | B5: =COUNTIFS('All Keywords'!$G$2:$G$1170,A5) -> 126 | C5: =SUMIFS('All Keywords'!$B$2:$B$1170,'All Keywords'!$G$2:$G$1170,A5) -> 29450 | D5: =IFERROR(AVERAGEIFS('All Keywords'!$C$2:$C$1170,'All Keywords'!$G$2:$G$1170,A5),"") -> 19.64
A6: India – general marketing/SEO | B6: =COUNTIFS('All Keywords'!$G$2:$G$1170,A6) -> 458 | C6: =SUMIFS('All Keywords'!$B$2:$B$1170,'All Keywords'!$G$2:$G$1170,A6) -> 168860 | D6: =IFERROR(AVERAGEIFS('All Keywords'!$C$2:$C$1170,'All Keywords'!$G$2:$G$1170,A6),"") -> 20.521834
A7: Abroad (India-database volume – verify in US/UK/UAE DB) | B7: =COUNTIFS('All Keywords'!$G$2:$G$1170,A7) -> 60 | C7: =SUMIFS('All Keywords'!$B$2:$B$1170,'All Keywords'!$G$2:$G$1170,A7) -> 14270 | D7: =IFERROR(AVERAGEIFS('All Keywords'!$C$2:$C$1170,'All Keywords'!$G$2:$G$1170,A7),"") -> 21.116667
A8: Outsourcing / white-label | B8: =COUNTIFS('All Keywords'!$G$2:$G$1170,A8) -> 15 | C8: =SUMIFS('All Keywords'!$B$2:$B$1170,'All Keywords'!$G$2:$G$1170,A8) -> 4950 | D8: =IFERROR(AVERAGEIFS('All Keywords'!$C$2:$C$1170,'All Keywords'!$G$2:$G$1170,A8),"") -> 17.733333
A9: Other industries | B9: =COUNTIFS('All Keywords'!$G$2:$G$1170,A9) -> 63 | C9: =SUMIFS('All Keywords'!$B$2:$B$1170,'All Keywords'!$G$2:$G$1170,A9) -> 22260 | D9: =IFERROR(AVERAGEIFS('All Keywords'!$C$2:$C$1170,'All Keywords'!$G$2:$G$1170,A9),"") -> 18.619048
A10: EXCLUDED – jobs/training/brands/irrelevant | B10: =COUNTIFS('All Keywords'!$G$2:$G$1170,A10) -> 69 | C10: =SUMIFS('All Keywords'!$B$2:$B$1170,'All Keywords'!$G$2:$G$1170,A10) -> 34170 | D10: =IFERROR(AVERAGEIFS('All Keywords'!$C$2:$C$1170,'All Keywords'!$G$2:$G$1170,A10),"") -> 20.058824
A11: EXCLUDED – other Indian city | B11: =COUNTIFS('All Keywords'!$G$2:$G$1170,A11) -> 362 | C11: =SUMIFS('All Keywords'!$B$2:$B$1170,'All Keywords'!$G$2:$G$1170,A11) -> 161620 | D11: =IFERROR(AVERAGEIFS('All Keywords'!$C$2:$C$1170,'All Keywords'!$G$2:$G$1170,A11),"") -> 18.116022
