Workbook

Sheet How to Use
A1: Niche Keyword Validation – Semrush Check
A2: Purpose: compare 4 agency niches on real search volume, CPC and keyword difficulty before committing.
A4: STEPS
A5: 1. Open Semrush → Keyword Overview → paste a list from the 'Paste Lists' sheet (up to 100 keywords per run).
A6: 2. Set the database shown above each list (IN = India, US = United States). CPC in Semrush is in USD.
A7: 3. Export the results (CSV), or type Volume, CPC and KD % into the YELLOW cells on the 'Keywords' sheet.
A8: Easiest: just upload the Semrush CSV exports in the chat and Claude will fill this sheet and analyse it.
A9: 4. The 'Niche Summary' sheet calculates totals, difficulty and an opportunity score automatically.
A11: LEGEND
A12: Yellow cells = inputs you fill from Semrush. All other cells are formulas – do not overwrite.
A13: Agency-side = what business owners search when looking to HIRE an agency (competition for your own website).
A14: Market-side = what their customers/buyers search (proves the niche's businesses have demand worth paying for).
... A19: EXAMPLE ROW (illustrative format only – not real data)
A20: Niche | B20: Keyword Type | C20: Database | D20: Keyword | E20: Volume | F20: CPC (USD) | G20: KD % | H20: Intent
A21: B. Solar & Energy | B21: Market-side | C21: IN | D21: rooftop solar price | E21: 2400 | F21: 0.45 | G21: 28 | H21: Commercial

Sheet Keywords
A1: # | B1: Niche | C1: Keyword Type | D1: Semrush DB | E1: Keyword | F1: Volume | G1: CPC (USD) | H1: KD % | I1: Intent | J1: Value (Vol×CPC, USD) | K1: Difficulty | L1: Notes
A2: 1 | B2: A. B2B Export | C2: Agency-side | D2: IN | E2: export marketing agency india | F2: 0 | G2: 0 | H2: 10 | J2: =IF(AND(ISNUMBER(F2),ISNUMBER(G2)),F2*G2,"") -> 0 | K2: =IF(H2="","",IF(H2<30,"Easy",IF(H2<50,"Medium",IF(H2<70,"Hard","Very hard")))) -> Easy | L2: Semrush n/a (below tracking threshold) – entered as 0
A3: 2 | B3: A. B2B Export | C3: Agency-side | D3: IN | E3: b2b digital marketing agency india | F3: 90 | G3: 0.67 | H3: 24 | I3: Commercial | J3: =IF(AND(ISNUMBER(F3),ISNUMBER(G3)),F3*G3,"") -> 60.3 | K3: =IF(H3="","",IF(H3<30,"Easy",IF(H3<50,"Medium",IF(H3<70,"Hard","Very hard")))) -> Easy
A4: 3 | B4: A. B2B Export | C4: Agency-side | D4: IN | E4: digital marketing for manufacturers | F4: 170 | G4: 0.92 | H4: 23 | I4: Informational | J4: =IF(AND(ISNUMBER(F4),ISNUMBER(G4)),F4*G4,"") -> 156.4 | K4: =IF(H4="","",IF(H4<30,"Easy",IF(H4<50,"Medium",IF(H4<70,"Hard","Very hard")))) -> Easy
A5: 4 | B5: A. B2B Export | C5: Agency-side | D5: IN | E5: digital marketing for exporters | F5: 20 | G5: 0 | H5: 13 | I5: Informational | J5: =IF(AND(ISNUMBER(F5),ISNUMBER(G5)),F5*G5,"") -> 0 | K5: =IF(H5="","",IF(H5<30,"Easy",IF(H5<50,"Medium",IF(H5<70,"Hard","Very hard")))) -> Easy
A6: 5 | B6: A. B2B Export | C6: Agency-side | D6: IN | E6: seo for manufacturers | F6: 260 | G6: 2.04 | H6: 36 | I6: Informational | J6: =IF(AND(ISNUMBER(F6),ISNUMBER(G6)),F6*G6,"") -> 530.4 | K6: =IF(H6="","",IF(H6<30,"Easy",IF(H6<50,"Medium",IF(H6<70,"Hard","Very hard")))) -> Medium
A7: 6 | B7: A. B2B Export | C7: Agency-side | D7: IN | E7: b2b seo agency india | F7: 0 | G7: 0 | H7: 7 | I7: Commercial | J7: =IF(AND(ISNUMBER(F7),ISNUMBER(G7)),F7*G7,"") -> 0 | K7: =IF(H7="","",IF(H7<30,"Easy",IF(H7<50,"Medium",IF(H7<70,"Hard","Very hard")))) -> Easy
A8: 7 | B8: A. B2B Export | C8: Agency-side | D8: IN | E8: industrial marketing agency | F8: 20 | G8: 0.49 | H8: 9 | I8: Commercial | J8: =IF(AND(ISNUMBER(F8),ISNUMBER(G8)),F8*G8,"") -> 9.8 | K8: =IF(H8="","",IF(H8<30,"Easy",IF(H8<50,"Medium",IF(H8<70,"Hard","Very hard")))) -> Easy
A9: 8 | B9: A. B2B Export | C9: Agency-side | D9: IN | E9: manufacturing website design | F9: 30 | G9: 0.39 | H9: 18 | I9: Commercial | J9: =IF(AND(ISNUMBER(F9),ISNUMBER(G9)),F9*G9,"") -> 11.7 | K9: =IF(H9="","",IF(H9<30,"Easy",IF(H9<50,"Medium",IF(H9<70,"Hard","Very hard")))) -> Easy
A10: 9 | B10: A. B2B Export | C10: Agency-side | D10: IN | E10: b2b lead generation company india | F10: 210 | G10: 0.87 | H10: 16 | I10: Informational | J10: =IF(AND(ISNUMBER(F10),ISNUMBER(G10)),F10*G10,"") -> 182.7 | K10: =IF(H10="","",IF(H10<30,"Easy",IF(H10<50,"Medium",IF(H10<70,"Hard","Very hard")))) -> Easy
A11: 10 | B11: A. B2B Export | C11: Agency-side | D11: IN | E11: export lead generation | F11: 30 | G11: 0.57 | H11: 5 | I11: Informational | J11: =IF(AND(ISNUMBER(F11),ISNUMBER(G11)),F11*G11,"") -> 17.1 | K11: =IF(H11="","",IF(H11<30,"Easy",IF(H11<50,"Medium",IF(H11<70,"Hard","Very hard")))) -> Easy
A12: 11 | B12: A. B2B Export | C12: Agency-side | D12: IN | E12: how to get international buyers | F12: 20 | G12: 0.24 | H12: 19 | I12: Informational | J12: =IF(AND(ISNUMBER(F12),ISNUMBER(G12)),F12*G12,"") -> 4.8 | K12: =IF(H12="","",IF(H12<30,"Easy",IF(H12<50,"Medium",IF(H12<70,"Hard","Very hard")))) -> Easy
A13: 12 | B13: A. B2B Export | C13: Agency-side | D13: IN | E13: how to find buyers for export | F13: 390 | G13: 0.22 | H13: 15 | I13: Informational | J13: =IF(AND(ISNUMBER(F13),ISNUMBER(G13)),F13*G13,"") -> 85.8 | K13: =IF(H13="","",IF(H13<30,"Easy",IF(H13<50,"Medium",IF(H13<70,"Hard","Very hard")))) -> Easy
A14: 13 | B14: A. B2B Export | C14: Agency-side | D14: IN | E14: how to get export orders | F14: 30 | G14: 0.18 | H14: 8 | I14: Informational | J14: =IF(AND(ISNUMBER(F14),ISNUMBER(G14)),F14*G14,"") -> 5.4 | K14: =IF(H14="","",IF(H14<30,"Easy",IF(H14<50,"Medium",IF(H14<70,"Hard","Very hard")))) -> Easy
A15: 14 | B15: A. B2B Export | C15: Agency-side | D15: IN | E15: linkedin marketing for b2b companies | F15: 0 | G15: 0 | H15: 59 | J15: =IF(AND(ISNUMBER(F15),ISNUMBER(G15)),F15*G15,"") -> 0 | K15: =IF(H15="","",IF(H15<30,"Easy",IF(H15<50,"Medium",IF(H15<70,"Hard","Very hard")))) -> Hard | L15: Semrush n/a (below tracking threshold) – entered as 0
A16: 15 | B16: A. B2B Export | C16: Agency-side | D16: IN | E16: google ads for manufacturers | F16: 0 | G16: 0 | H16: 18 | J16: =IF(AND(ISNUMBER(F16),ISNUMBER(G16)),F16*G16,"") -> 0 | K16: =IF(H16="","",IF(H16<30,"Easy",IF(H16<50,"Medium",IF(H16<70,"Hard","Very hard")))) -> Easy | L16: Semrush n/a (below tracking threshold) – entered as 0
A17: 16 | B17: A. B2B Export | C17: Agency-side | D17: IN | E17: b2b website development company | F17: 20 | G17: 0 | H17: 5 | I17: Informational | J17: =IF(AND(ISNUMBER(F17),ISNUMBER(G17)),F17*G17,"") -> 0 | K17: =IF(H17="","",IF(H17<30,"Easy",IF(H17<50,"Medium",IF(H17<70,"Hard","Very hard")))) -> Easy
A18: 17 | B18: A. B2B Export | C18: Agency-side | D18: IN | E18: industrial seo services | F18: 0 | G18: 0 | H18: 20 | J18: =IF(AND(ISNUMBER(F18),ISNUMBER(G18)),F18*G18,"") -> 0 | K18: =IF(H18="","",IF(H18<30,"Easy",IF(H18<50,"Medium",IF(H18<70,"Hard","Very hard")))) -> Easy | L18: Semrush n/a (below tracking threshold) – entered as 0
A19: 18 | B19: A. B2B Export | C19: Agency-side | D19: IN | E19: export business website | F19: 140 | G19: 0.3 | H19: 46 | I19: Informational | J19: =IF(AND(ISNUMBER(F19),ISNUMBER(G19)),F19*G19,"") -> 42 | K19: =IF(H19="","",IF(H19<30,"Easy",IF(H19<50,"Medium",IF(H19<70,"Hard","Very hard")))) -> Medium
A20: 19 | B20: A. B2B Export | C20: Agency-side | D20: IN | E20: alternative to indiamart | F20: 10 | G20: 0.17 | H20: 17 | I20: Commercial | J20: =IF(AND(ISNUMBER(F20),ISNUMBER(G20)),F20*G20,"") -> 1.7 | K20: =IF(H20="","",IF(H20<30,"Easy",IF(H20<50,"Medium",IF(H20<70,"Hard","Very hard")))) -> Easy
A21: 20 | B21: A. B2B Export | C21: Agency-side | D21: IN | E21: digital marketing agency for manufacturing companies | F21: 0 | G21: 0 | H21: 17 | J21: =IF(AND(ISNUMBER(F21),ISNUMBER(G21)),F21*G21,"") -> 0 | K21: =IF(H21="","",IF(H21<30,"Easy",IF(H21<50,"Medium",IF(H21<70,"Hard","Very hard")))) -> Easy | L21: Semrush n/a (below tracking threshold) – entered as 0
A22: 21 | B22: A. B2B Export | C22: Market-side | D22: US | E22: cnc machining services india | J22: =IF(AND(ISNUMBER(F22),ISNUMBER(G22)),F22*G22,"") | K22: =IF(H22="","",IF(H22<30,"Easy",IF(H22<50,"Medium",IF(H22<70,"Hard","Very hard"))))
A23: 22 | B23: A. B2B Export | C23: Market-side | D23: US | E23: precision machined components manufacturer india | J23: =IF(AND(ISNUMBER(F23),ISNUMBER(G23)),F23*G23,"") | K23: =IF(H23="","",IF(H23<30,"Easy",IF(H23<50,"Medium",IF(H23<70,"Hard","Very hard"))))
A24: 23 | B24: A. B2B Export | C24: Market-side | D24: US | E24: auto parts manufacturer india | J24: =IF(AND(ISNUMBER(F24),ISNUMBER(G24)),F24*G24,"") | K24: =IF(H24="","",IF(H24<30,"Easy",IF(H24<50,"Medium",IF(H24<70,"Hard","Very hard"))))
A25: 24 | B25: A. B2B Export | C25: Market-side | D25: US | E25: automotive components suppliers india | J25: =IF(AND(ISNUMBER(F25),ISNUMBER(G25)),F25*G25,"") | K25: =IF(H25="","",IF(H25<30,"Easy",IF(H25<50,"Medium",IF(H25<70,"Hard","Very hard"))))
A26: 25 | B26: A. B2B Export | C26: Market-side | D26: US | E26: forging manufacturers india | J26: =IF(AND(ISNUMBER(F26),ISNUMBER(G26)),F26*G26,"") | K26: =IF(H26="","",IF(H26<30,"Easy",IF(H26<50,"Medium",IF(H26<70,"Hard","Very hard"))))
A27: 26 | B27: A. B2B Export | C27: Market-side | D27: US | E27: casting manufacturers india | J27: =IF(AND(ISNUMBER(F27),ISNUMBER(G27)),F27*G27,"") | K27: =IF(H27="","",IF(H27<30,"Easy",IF(H27<50,"Medium",IF(H27<70,"Hard","Very hard"))))
A28: 27 | B28: A. B2B Export | C28: Market-side | D28: US | E28: industrial pumps manufacturer india | J28: =IF(AND(ISNUMBER(F28),ISNUMBER(G28)),F28*G28,"") | K28: =IF(H28="","",IF(H28<30,"Easy",IF(H28<50,"Medium",IF(H28<70,"Hard","Very hard"))))
A29: 28 | B29: A. B2B Export | C29: Market-side | D29: US | E29: submersible pump manufacturer india | J29: =IF(AND(ISNUMBER(F29),ISNUMBER(G29)),F29*G29,"") | K29: =IF(H29="","",IF(H29<30,"Easy",IF(H29<50,"Medium",IF(H29<70,"Hard","Very hard"))))
A30: 29 | B30: A. B2B Export | C30: Market-side | D30: US | E30: electric motor manufacturer india | J30: =IF(AND(ISNUMBER(F30),ISNUMBER(G30)),F30*G30,"") | K30: =IF(H30="","",IF(H30<30,"Easy",IF(H30<50,"Medium",IF(H30<70,"Hard","Very hard"))))
A31: 30 | B31: A. B2B Export | C31: Market-side | D31: US | E31: pcb assembly india | J31: =IF(AND(ISNUMBER(F31),ISNUMBER(G31)),F31*G31,"") | K31: =IF(H31="","",IF(H31<30,"Easy",IF(H31<50,"Medium",IF(H31<70,"Hard","Very hard"))))
A32: 31 | B32: A. B2B Export | C32: Market-side | D32: US | E32: electronics manufacturing services india | J32: =IF(AND(ISNUMBER(F32),ISNUMBER(G32)),F32*G32,"") | K32: =IF(H32="","",IF(H32<30,"Easy",IF(H32<50,"Medium",IF(H32<70,"Hard","Very hard"))))
A33: 32 | B33: A. B2B Export | C33: Market-side | D33: US | E33: contract manufacturing india | J33: =IF(AND(ISNUMBER(F33),ISNUMBER(G33)),F33*G33,"") | K33: =IF(H33="","",IF(H33<30,"Easy",IF(H33<50,"Medium",IF(H33<70,"Hard","Very hard"))))
... A51: 50 | B51: A. B2B Export | C51: Market-side | D51: US | E51: china plus one sourcing india | J51: =IF(AND(ISNUMBER(F51),ISNUMBER(G51)),F51*G51,"") | K51: =IF(H51="","",IF(H51<30,"Easy",IF(H51<50,"Medium",IF(H51<70,"Hard","Very hard"))))
A52: 51 | B52: B. Solar & Energy | C52: Agency-side | D52: IN | E52: solar marketing agency | F52: 30 | G52: 0.35 | H52: 17 | I52: Commercial | J52: =IF(AND(ISNUMBER(F52),ISNUMBER(G52)),F52*G52,"") -> 10.5 | K52: =IF(H52="","",IF(H52<30,"Easy",IF(H52<50,"Medium",IF(H52<70,"Hard","Very hard")))) -> Easy
A53: 52 | B53: B. Solar & Energy | C53: Agency-side | D53: IN | E53: digital marketing for solar companies | F53: 10 | G53: 0.31 | H53: 13 | I53: Informational | J53: =IF(AND(ISNUMBER(F53),ISNUMBER(G53)),F53*G53,"") -> 3.1 | K53: =IF(H53="","",IF(H53<30,"Easy",IF(H53<50,"Medium",IF(H53<70,"Hard","Very hard")))) -> Easy
A54: 53 | B54: B. Solar & Energy | C54: Agency-side | D54: IN | E54: solar lead generation | F54: 140 | G54: 1.56 | H54: 14 | I54: Informational | J54: =IF(AND(ISNUMBER(F54),ISNUMBER(G54)),F54*G54,"") -> 218.4 | K54: =IF(H54="","",IF(H54<30,"Easy",IF(H54<50,"Medium",IF(H54<70,"Hard","Very hard")))) -> Easy
A55: 54 | B55: B. Solar & Energy | C55: Agency-side | D55: IN | E55: solar leads india | F55: 20 | G55: 0 | H55: 2 | I55: Commercial | J55: =IF(AND(ISNUMBER(F55),ISNUMBER(G55)),F55*G55,"") -> 0 | K55: =IF(H55="","",IF(H55<30,"Easy",IF(H55<50,"Medium",IF(H55<70,"Hard","Very hard")))) -> Easy
A56: 55 | B56: B. Solar & Energy | C56: Agency-side | D56: IN | E56: seo for solar companies | F56: 20 | G56: 0 | H56: 23 | I56: Informational | J56: =IF(AND(ISNUMBER(F56),ISNUMBER(G56)),F56*G56,"") -> 0 | K56: =IF(H56="","",IF(H56<30,"Easy",IF(H56<50,"Medium",IF(H56<70,"Hard","Very hard")))) -> Easy
A57: 56 | B57: B. Solar & Energy | C57: Agency-side | D57: IN | E57: solar company website design | F57: 0 | G57: 0 | H57: 25 | J57: =IF(AND(ISNUMBER(F57),ISNUMBER(G57)),F57*G57,"") -> 0 | K57: =IF(H57="","",IF(H57<30,"Easy",IF(H57<50,"Medium",IF(H57<70,"Hard","Very hard")))) -> Easy | L57: Semrush n/a (below tracking threshold) – entered as 0
...

Sheet Niche Summary
A1: Niche Summary – auto-calculated from the Keywords sheet
A2: Fill the yellow cells on 'Keywords'; everything here updates automatically. Blank until data is entered.
A4: Niche | B4: Keywords listed | C4: Keywords filled | D4: Total volume | E4: Agency-side volume | F4: Market-side volume | G4: Weighted avg CPC (USD) | H4: Avg KD % (all) | I4: Avg KD % (agency-side) | J4: Total value (USD/mo) | K4: Opportunity score | L4: Rank
A5: A. B2B Export | B5: =COUNTIFS(Keywords!$B$2:$B$176,A5) -> 50 | C5: =COUNTIFS(Keywords!$B$2:$B$176,A5,Keywords!$F$2:$F$176,"<>") -> 20 | D5: =IF(C5=0,"",SUMIFS(Keywords!$F$2:$F$176,Keywords!$B$2:$B$176,A5)) -> 1440 | E5: =IF(C5=0,"",SUMIFS(Keywords!$F$2:$F$176,Keywords!$B$2:$B$176,A5,Keywords!$C$2:$C$176,"Agency-side")) -> 1440 | F5: =IF(C5=0,"",SUMIFS(Keywords!$F$2:$F$176,Keywords!$B$2:$B$176,A5,Keywords!$C$2:$C$176,"Market-side")) -> 0 | G5: =IF(C5=0,"",IFERROR(J5/D5,"")) -> 0.76951389 | H5: =IFERROR(AVERAGEIFS(Keywords!$H$2:$H$176,Keywords!$B$2:$B$176,A5,Keywords!$H$2:$H$176,"<>"),"") -> 19.25 | I5: =IFERROR(AVERAGEIFS(Keywords!$H$2:$H$176,Keywords!$B$2:$B$176,A5,Keywords!$C$2:$C$176,"Agency-side",Keywords!$H$2:$H$176,"<>"),"") -> 19.25 | J5: =IF(C5=0,"",SUMIFS(Keywords!$J$2:$J$176,Keywords!$B$2:$B$176,A5)) -> 1108.1 | K5: =IF(OR(J5="",H5=""),"",J5/MAX(H5,1)) -> 57.563636 | L5: =IF(K5="","",COUNTIF($K$5:$K$8,">"&K5)+1) -> 3
A6: B. Solar & Energy | B6: =COUNTIFS(Keywords!$B$2:$B$176,A6) -> 50 | C6: =COUNTIFS(Keywords!$B$2:$B$176,A6,Keywords!$F$2:$F$176,"<>") -> 15 | D6: =IF(C6=0,"",SUMIFS(Keywords!$F$2:$F$176,Keywords!$B$2:$B$176,A6)) -> 220 | E6: =IF(C6=0,"",SUMIFS(Keywords!$F$2:$F$176,Keywords!$B$2:$B$176,A6,Keywords!$C$2:$C$176,"Agency-side")) -> 220 | F6: =IF(C6=0,"",SUMIFS(Keywords!$F$2:$F$176,Keywords!$B$2:$B$176,A6,Keywords!$C$2:$C$176,"Market-side")) -> 0 | G6: =IF(C6=0,"",IFERROR(J6/D6,"")) -> 1.0545455 | H6: =IFERROR(AVERAGEIFS(Keywords!$H$2:$H$176,Keywords!$B$2:$B$176,A6,Keywords!$H$2:$H$176,"<>"),"") -> 18 | I6: =IFERROR(AVERAGEIFS(Keywords!$H$2:$H$176,Keywords!$B$2:$B$176,A6,Keywords!$C$2:$C$176,"Agency-side",Keywords!$H$2:$H$176,"<>"),"") -> 18 | J6: =IF(C6=0,"",SUMIFS(Keywords!$J$2:$J$176,Keywords!$B$2:$B$176,A6)) -> 232 | K6: =IF(OR(J6="",H6=""),"",J6/MAX(H6,1)) -> 12.888889 | L6: =IF(K6="","",COUNTIF($K$5:$K$8,">"&K6)+1) -> 4
A7: C. Cross-border E-com | B7: =COUNTIFS(Keywords!$B$2:$B$176,A7) -> 50 | C7: =COUNTIFS(Keywords!$B$2:$B$176,A7,Keywords!$F$2:$F$176,"<>") -> 20 | D7: =IF(C7=0,"",SUMIFS(Keywords!$F$2:$F$176,Keywords!$B$2:$B$176,A7)) -> 7020 | E7: =IF(C7=0,"",SUMIFS(Keywords!$F$2:$F$176,Keywords!$B$2:$B$176,A7,Keywords!$C$2:$C$176,"Agency-side")) -> 7020 | F7: =IF(C7=0,"",SUMIFS(Keywords!$F$2:$F$176,Keywords!$B$2:$B$176,A7,Keywords!$C$2:$C$176,"Market-side")) -> 0 | G7: =IF(C7=0,"",IFERROR(J7/D7,"")) -> 0.37082621 | H7: =IFERROR(AVERAGEIFS(Keywords!$H$2:$H$176,Keywords!$B$2:$B$176,A7,Keywords!$H$2:$H$176,"<>"),"") -> 34.45 | I7: =IFERROR(AVERAGEIFS(Keywords!$H$2:$H$176,Keywords!$B$2:$B$176,A7,Keywords!$C$2:$C$176,"Agency-side",Keywords!$H$2:$H$176,"<>"),"") -> 34.45 | J7: =IF(C7=0,"",SUMIFS(Keywords!$J$2:$J$176,Keywords!$B$2:$B$176,A7)) -> 2603.2 | K7: =IF(OR(J7="",H7=""),"",J7/MAX(H7,1)) -> 75.564586 | L7: =IF(K7="","",COUNTIF($K$5:$K$8,">"&K7)+1) -> 2
A8: F. E-com Agency (baseline) | B8: =COUNTIFS(Keywords!$B$2:$B$176,A8) -> 25 | C8: =COUNTIFS(Keywords!$B$2:$B$176,A8,Keywords!$F$2:$F$176,"<>") -> 25 | D8: =IF(C8=0,"",SUMIFS(Keywords!$F$2:$F$176,Keywords!$B$2:$B$176,A8)) -> 12570 | E8: =IF(C8=0,"",SUMIFS(Keywords!$F$2:$F$176,Keywords!$B$2:$B$176,A8,Keywords!$C$2:$C$176,"Agency-side")) -> 12570 | F8: =IF(C8=0,"",SUMIFS(Keywords!$F$2:$F$176,Keywords!$B$2:$B$176,A8,Keywords!$C$2:$C$176,"Market-side")) -> 0 | G8: =IF(C8=0,"",IFERROR(J8/D8,"")) -> 0.50319809 | H8: =IFERROR(AVERAGEIFS(Keywords!$H$2:$H$176,Keywords!$B$2:$B$176,A8,Keywords!$H$2:$H$176,"<>"),"") -> 16.28 | I8: =IFERROR(AVERAGEIFS(Keywords!$H$2:$H$176,Keywords!$B$2:$B$176,A8,Keywords!$C$2:$C$176,"Agency-side",Keywords!$H$2:$H$176,"<>"),"") -> 16.28 | J8: =IF(C8=0,"",SUMIFS(Keywords!$J$2:$J$176,Keywords!$B$2:$B$176,A8)) -> 6325.2 | K8: =IF(OR(J8="",H8=""),"",J8/MAX(H8,1)) -> 388.5258 | L8: =IF(K8="","",COUNTIF($K$5:$K$8,">"&K8)+1) -> 1
A10: How to read it:
A11: • Market-side volume + CPC high → the niche's businesses have money and real customer demand.
A12: • Agency-side KD low → few agencies compete for that niche on Google, so your own site can rank faster (the 'untouched' test).
A13: • Opportunity score = Total value ÷ Avg KD. Compare niches against the F baseline (general e-commerce agency).
A14: • Sanity rule: a niche wins only if it also passes the landing-page ad test and 20 owner phone calls (Steps 2–4 of the plan).

Sheet Paste Lists
A1: Copy one column at a time into Semrush Keyword Overview (bulk). Set the database shown in row 3.
A2: A. B2B Export – Agency-side | B2: A. B2B Export – Market-side | C2: B. Solar & Energy – Agency-side | D2: B. Solar & Energy – Market-side | E2: C. Cross-border E-com – Agency-side | F2: C. Cross-border E-com – Market-side | G2: F. E-com Agency (baseline) – Agency-side
A3: Semrush database: IN | B3: Semrush database: US | C3: Semrush database: IN | D3: Semrush database: IN | E3: Semrush database: IN | F3: Semrush database: US | G3: Semrush database: IN
A4: export marketing agency india | B4: cnc machining services india | C4: solar marketing agency | D4: rooftop solar | E4: amazon global selling | F4: kanchipuram silk saree | G4: ecommerce website development company
A5: b2b digital marketing agency india | B5: precision machined components manufacturer india | C5: digital marketing for solar companies | D5: rooftop solar price | E5: amazon global selling india | F5: kanjeevaram saree online usa | G5: ecommerce website development chennai
A6: digital marketing for manufacturers | B6: auto parts manufacturer india | C6: solar lead generation | D6: solar panel price in chennai | E6: how to sell on amazon usa from india | F6: silk sarees online | G6: shopify development company india
A7: digital marketing for exporters | B7: automotive components suppliers india | C7: solar leads india | D7: solar panel installation chennai | E7: sell on amazon us from india | F7: indian sarees online usa | G7: shopify experts india
A8: seo for manufacturers | B8: forging manufacturers india | C8: seo for solar companies | D8: rooftop solar chennai | E8: etsy seller india | F8: indian ethnic wear online usa | G8: shopify website development chennai
A9: b2b seo agency india | B9: casting manufacturers india | C9: solar company website design | D9: solar panel coimbatore | E9: how to sell on etsy from india | F9: indian jewelry online | G9: woocommerce development company
A10: industrial marketing agency | B10: industrial pumps manufacturer india | C10: google ads for solar companies | D10: solar companies in chennai | E10: shopify international store india | F10: temple jewelry | G10: ecommerce seo agency
A11: manufacturing website design | B11: submersible pump manufacturer india | C11: facebook ads for solar | D11: solar companies in coimbatore | E11: ecommerce export from india | F11: indian grocery online usa | G11: ecommerce seo services india
A12: b2b lead generation company india | B12: electric motor manufacturer india | C12: how to get solar leads | D12: solar subsidy tamil nadu | E12: cross border ecommerce india | F12: indian snacks online | G12: ecommerce marketing agency
A13: export lead generation | B13: pcb assembly india | C13: solar installer marketing | D13: pm surya ghar | E13: amazon account management services | F13: south indian filter coffee | G13: ecommerce marketing agency india
... A18: google ads for manufacturers | B18: wind turbine components india | C18: solar crm software india | D18: 10kw solar system price | E18: ecommerce export business | F18: ayurvedic hair oil | G18: flipkart ads management
A19: b2b website development company | B19: leather goods manufacturer india | D19: on grid solar system price | E19: amazon global selling consultant | F19: herbal hair oil | G19: flipkart account management services
A20: industrial seo services | B20: leather bags manufacturer india | D20: solar panel for home price | E20: how to export products from india online | F20: organic cotton t shirts | G20: blinkit ads
A21: export business website | B21: t shirt manufacturer india | D21: solar inverter price | E21: amazon fba from india | F21: cotton kurtis online | G21: quick commerce marketing agency
A22: alternative to indiamart | B22: private label clothing manufacturer india | D22: solar battery price | E22: noon seller from india | F22: brass pooja items | G22: digital marketing agency chennai
A23: digital marketing agency for manufacturing companies | B23: organic cotton t shirt manufacturer | D23: solar water heater price | E23: sell on amazon uae from india | F23: brass lamp | G23: seo company in chennai
B24: knitwear manufacturer india | D24: solar power plant for factory | F24: copper water bottle | G24: google ads agency chennai
B25: home textiles manufacturer india | D25: commercial solar installation | F25: tanjore painting | G25: meta ads agency india
B26: towel manufacturer india | D26: industrial rooftop solar | F26: handloom cotton saree | G26: ecommerce website cost in india
B27: spice exporters india | D27: open access solar tamil nadu | F27: banana chips online | G27: shopify store setup service
B28: coconut products exporter india | D28: solar epc companies in india | F28: millet snacks | G28: amazon seller account management chennai
B29: coir products manufacturer | D29: solar net metering tamil nadu | F29: murukku online
B30: rubber products manufacturer india | D30: tangedco solar | F30: indian sweets online usa
B31: engineering components sourcing india | D31: home battery storage india | F31: coconut oil cold pressed
B32: outsourcing manufacturing to india | D32: ev charger installation chennai | F32: wooden toys india
B33: china plus one sourcing india | D33: ev charging station franchise | F33: indian gifts online usa
D34: solar panel cleaning service
D35: solar street light price
D36: solar pump price
D37: pm kusum yojana
D38: solar amc service
